{
 "cells": [
  {
   "cell_type": "code",
   "execution_count": 8,
   "metadata": {},
   "outputs": [],
   "source": [
    "import tensorflow_hub as hub\n",
    "import tensorflow as tf\n",
    "from matplotlib import pyplot as plt\n",
    "import numpy as np\n",
    "import cv2"
   ]
  },
  {
   "cell_type": "code",
   "execution_count": 9,
   "metadata": {},
   "outputs": [],
   "source": [
    "model = hub.load('https://tfhub.dev/google/magenta/arbitrary-image-stylization-v1-256/2')"
   ]
  },
  {
   "cell_type": "code",
   "execution_count": 10,
   "metadata": {},
   "outputs": [],
   "source": [
    "def load_image(img_path):\n",
    "    img = tf.io.read_file(img_path)\n",
    "    img = tf.image.decode_image(img, channels=3)\n",
    "    img = tf.image.convert_image_dtype(img, tf.float32)\n",
    "    img = img[tf.newaxis, :]\n",
    "    return img"
   ]
  },
  {
   "cell_type": "code",
   "execution_count": 11,
   "metadata": {},
   "outputs": [
    {
     "name": "stderr",
     "output_type": "stream",
     "text": [
      "ERROR:root:Internal Python error in the inspect module.\n",
      "Below is the traceback from this internal error.\n",
      "\n"
     ]
    },
    {
     "name": "stdout",
     "output_type": "stream",
     "text": [
      "Traceback (most recent call last):\n",
      "  File \"/Library/Frameworks/Python.framework/Versions/3.8/lib/python3.8/site-packages/IPython/core/interactiveshell.py\", line 3331, in run_code\n",
      "    exec(code_obj, self.user_global_ns, self.user_ns)\n",
      "  File \"<ipython-input-11-82f57abe001b>\", line 1, in <module>\n",
      "    content_image = load_image('Profile.jpg')\n",
      "  File \"<ipython-input-10-67bbebcc3f45>\", line 2, in load_image\n",
      "    img = tf.io.read_file(img_path)\n",
      "  File \"/Library/Frameworks/Python.framework/Versions/3.8/lib/python3.8/site-packages/tensorflow/python/ops/gen_io_ops.py\", line 558, in read_file\n",
      "    return read_file_eager_fallback(\n",
      "  File \"/Library/Frameworks/Python.framework/Versions/3.8/lib/python3.8/site-packages/tensorflow/python/ops/gen_io_ops.py\", line 596, in read_file_eager_fallback\n",
      "    _result = _execute.execute(b\"ReadFile\", 1, inputs=_inputs_flat,\n",
      "  File \"/Library/Frameworks/Python.framework/Versions/3.8/lib/python3.8/site-packages/tensorflow/python/eager/execute.py\", line 59, in quick_execute\n",
      "    tensors = pywrap_tfe.TFE_Py_Execute(ctx._handle, device_name, op_name,\n",
      "tensorflow.python.framework.errors_impl.NotFoundError: Profile.jpg; No such file or directory [Op:ReadFile]\n",
      "\n",
      "During handling of the above exception, another exception occurred:\n",
      "\n",
      "Traceback (most recent call last):\n",
      "  File \"/Library/Frameworks/Python.framework/Versions/3.8/lib/python3.8/site-packages/IPython/core/interactiveshell.py\", line 2044, in showtraceback\n",
      "    stb = value._render_traceback_()\n",
      "AttributeError: 'NotFoundError' object has no attribute '_render_traceback_'\n",
      "\n",
      "During handling of the above exception, another exception occurred:\n",
      "\n",
      "Traceback (most recent call last):\n",
      "  File \"/Library/Frameworks/Python.framework/Versions/3.8/lib/python3.8/site-packages/IPython/core/ultratb.py\", line 1148, in get_records\n",
      "    return _fixed_getinnerframes(etb, number_of_lines_of_context, tb_offset)\n",
      "  File \"/Library/Frameworks/Python.framework/Versions/3.8/lib/python3.8/site-packages/IPython/core/ultratb.py\", line 316, in wrapped\n",
      "    return f(*args, **kwargs)\n",
      "  File \"/Library/Frameworks/Python.framework/Versions/3.8/lib/python3.8/site-packages/IPython/core/ultratb.py\", line 350, in _fixed_getinnerframes\n",
      "    records = fix_frame_records_filenames(inspect.getinnerframes(etb, context))\n",
      "  File \"/Library/Frameworks/Python.framework/Versions/3.8/lib/python3.8/inspect.py\", line 1503, in getinnerframes\n",
      "    frameinfo = (tb.tb_frame,) + getframeinfo(tb, context)\n",
      "  File \"/Library/Frameworks/Python.framework/Versions/3.8/lib/python3.8/inspect.py\", line 1461, in getframeinfo\n",
      "    filename = getsourcefile(frame) or getfile(frame)\n",
      "  File \"/Library/Frameworks/Python.framework/Versions/3.8/lib/python3.8/inspect.py\", line 708, in getsourcefile\n",
      "    if getattr(getmodule(object, filename), '__loader__', None) is not None:\n",
      "  File \"/Library/Frameworks/Python.framework/Versions/3.8/lib/python3.8/inspect.py\", line 737, in getmodule\n",
      "    file = getabsfile(object, _filename)\n",
      "  File \"/Library/Frameworks/Python.framework/Versions/3.8/lib/python3.8/inspect.py\", line 721, in getabsfile\n",
      "    return os.path.normcase(os.path.abspath(_filename))\n",
      "  File \"/Library/Frameworks/Python.framework/Versions/3.8/lib/python3.8/posixpath.py\", line 379, in abspath\n",
      "    cwd = os.getcwd()\n",
      "PermissionError: [Errno 1] Operation not permitted\n"
     ]
    },
    {
     "ename": "NotFoundError",
     "evalue": "Profile.jpg; No such file or directory [Op:ReadFile]",
     "output_type": "error",
     "traceback": [
      "\u001b[0;31m---------------------------------------------------------------------------\u001b[0m"
     ]
    }
   ],
   "source": [
    "content_image = load_image('Profile.jpg')\n",
    "style_image = load_image('monet.jpg')"
   ]
  },
  {
   "cell_type": "code",
   "execution_count": null,
   "metadata": {},
   "outputs": [],
   "source": []
  }
 ],
 "metadata": {
  "kernelspec": {
   "display_name": "Python 3",
   "language": "python",
   "name": "python3"
  },
  "language_info": {
   "codemirror_mode": {
    "name": "ipython",
    "version": 3
   },
   "file_extension": ".py",
   "mimetype": "text/x-python",
   "name": "python",
   "nbconvert_exporter": "python",
   "pygments_lexer": "ipython3",
   "version": "3.8.3"
  }
 },
 "nbformat": 4,
 "nbformat_minor": 4
}
